PS C:\Users\aljal\Desktop\MDE\Source_Codes\screen_configuration_APP> & C:/Users/aljal/AppData/Local/Programs/Python/Python312/python.exe c:/Users/aljal/Desktop/MDE/Source_Codes/screen_configuration_APP/app.py
üîç Configuration Loaded: Script Name = 'pattern_detection_v001.py', Repository URL = 'https://github.com/AljalaliAli/PatternDetection.git'
‚úÖ 'pattern_detection_v001.py' already exists. No download needed.
üü¢ Module 'pattern_detection_v001' already in sys.modules.
üîß Paths and settings extracted successfully.
[INFO] Configuration data loaded successfully.
üü¢ Configuration Tool initialized successfully. Launching UI...
[Debug] file_path: C:/Users/aljal/Desktop/MDE/Resources/ConfigFiles/TNC640/TNC640_T1_V010/templates/template_1.tiff 
match_val=1.0
match_val=1.0
*********************************************
Current match_values
 match_values = [1.0, 1.0]    temp_img_id = 1
*********************************************
[Debug] update_possible_machine_status called!
Exception in Tkinter callback
Traceback (most recent call last):
  File "C:\Users\aljal\AppData\Local\Programs\Python\Python312\Lib\tkinter\__init__.py", line 1968, in __call__
    return self.func(*args)
           ^^^^^^^^^^^^^^^^
  File "c:\Users\aljal\Desktop\MDE\Source_Codes\screen_configuration_APP\MachineStatusConditionsManager.py", line 352, in <lambda>  
    command=lambda: self.insert_condition_after(group, condition),
                    ^^^^^^^^^^^^^^^^^^^^^^^^^^^
AttributeError: 'MachineStatusConditionsManager' object has no attribute 'insert_condition_after'
Exception in Tkinter callback
Traceback (most recent call last):
  File "C:\Users\aljal\AppData\Local\Programs\Python\Python312\Lib\tkinter\__init__.py", line 1968, in __call__
    return self.func(*args)
           ^^^^^^^^^^^^^^^^
  File "c:\Users\aljal\Desktop\MDE\Source_Codes\screen_configuration_APP\MachineStatusConditionsManager.py", line 352, in <lambda>  
    command=lambda: self.insert_condition_after(group, condition),
                    ^^^^^^^^^^^^^^^^^^^^^^^^^^^
AttributeError: 'MachineStatusConditionsManager' object has no attribute 'insert_condition_after'
Exception in Tkinter callback
Traceback (most recent call last):
  File "C:\Users\aljal\AppData\Local\Programs\Python\Python312\Lib\tkinter\__init__.py", line 1968, in __call__
    return self.func(*args)
           ^^^^^^^^^^^^^^^^
  File "c:\Users\aljal\Desktop\MDE\Source_Codes\screen_configuration_APP\MachineStatusConditionsManager.py", line 352, in <lambda>  
    command=lambda: self.insert_condition_after(group, condition),
                    ^^^^^^^^^^^^^^^^^^^^^^^^^^^
AttributeError: 'MachineStatusConditionsManager' object has no attribute 'insert_condition_after'
Exception in Tkinter callback
Traceback (most recent call last):
  File "C:\Users\aljal\AppData\Local\Programs\Python\Python312\Lib\tkinter\__init__.py", line 1968, in __call__
    return self.func(*args)
           ^^^^^^^^^^^^^^^^
  File "c:\Users\aljal\Desktop\MDE\Source_Codes\screen_configuration_APP\MachineStatusConditionsManager.py", line 352, in <lambda>  
    command=lambda: self.insert_condition_after(group, condition),
                    ^^^^^^^^^^^^^^^^^^^^^^^^^^^
AttributeError: 'MachineStatusConditionsManager' object has no attribute 'insert_condition_after'
Exception in Tkinter callback
Traceback (most recent call last):
  File "C:\Users\aljal\AppData\Local\Programs\Python\Python312\Lib\tkinter\__init__.py", line 1968, in __call__
    return self.func(*args)
           ^^^^^^^^^^^^^^^^
  File "c:\Users\aljal\Desktop\MDE\Source_Codes\screen_configuration_APP\MachineStatusConditionsManager.py", line 359, in <lambda>  
    command=lambda: self.duplicate_condition(group, condition),
                    ^^^^^^^^^^^^^^^^^^^^^^^^
AttributeError: 'MachineStatusConditionsManager' object has no attribute 'duplicate_condition'
Exception in Tkinter callback
Traceback (most recent call last):
  File "C:\Users\aljal\AppData\Local\Programs\Python\Python312\Lib\tkinter\__init__.py", line 1968, in __call__
    return self.func(*args)
           ^^^^^^^^^^^^^^^^
  File "c:\Users\aljal\Desktop\MDE\Source_Codes\screen_configuration_APP\MachineStatusConditionsManager.py", line 352, in <lambda>  
    command=lambda: self.insert_condition_after(group, condition),
                    ^^^^^^^^^^^^^^^^^^^^^^^^^^^
AttributeError: 'MachineStatusConditionsManager' object has no attribute 'insert_condition_after'
Exception in Tkinter callback
Traceback (most recent call last):
  File "C:\Users\aljal\AppData\Local\Programs\Python\Python312\Lib\tkinter\__init__.py", line 1968, in __call__
    return self.func(*args)
           ^^^^^^^^^^^^^^^^
  File "c:\Users\aljal\Desktop\MDE\Source_Codes\screen_configuration_APP\MachineStatusConditionsManager.py", line 352, in <lambda>  
    command=lambda: self.insert_condition_after(group, condition),
                    ^^^^^^^^^^^^^^^^^^^^^^^^^^^
AttributeError: 'MachineStatusConditionsManager' object has no attribute 'insert_condition_after'